Workbook

Sheet README
A1: PK Residential Master Material Database - v1.0
A2: Purpose | B2: Knowledge base for automatic MTO/BOQ generation of 5-10 marla houses (Islamabad/Rawalpindi). It stores HOW to calculate quantities (work items, measurement rules, coefficients, mixes, wastage) - not fixed quantities.
A3: Built from | B3: 31-sheet drawing set (5 Marla, Mr. Sameer Shah, IBN-E-ASGHAR & Associates, 17-11-2025), the existing CostLens v0.4.0 app, Pakistani estimating practice and codes (see Sources).
A4: Data model | B4: Drawings -> ELEMENTS (Element_Library) -> WORK ITEMS (Work_Items: measured BOQ items with measurement rules) -> RECIPES (coefficients per unit work) -> MATERIALS (Material_Master). Material qty = Σ(WI qty × coefficient) × (1 + wastage).
A5: Colour legend | B5: Blue text = editable input/assumption. Black = formula. Green = cross-sheet lookup. Yellow fill = to be filled by user (rates, counts). Light-blue headers in Material_Master = the 9 required columns.
A6: Material_Master | B6: One row per procurable material. Mat_ID is the permanent key (never reuse). Formula_Key = RECIPE means quantities come from Recipes; otherwise see Calc_Methods grammar.
A7: Work_Items | B7: Measured BOQ items with measurement rule, engine formula expression, required inputs, default spec and mapping to legacy app codes.
A8: Recipes | B8: Work item -> material coefficients (live formulas linked to Coefficients and Mix_Design). Changing a coefficient updates all recipes.
A9: Coefficients | B9: All engineering constants/allowances with units, basis and source. Derived coefficients are formulas.
A10: Mix_Design | B10: Nominal mixes (PCC 1:4:8, RCC 1:2:4, 1:1.5:3, mortars) -> cement bags, sand, crush per cft/m3 using dry volume factors.
A11: Wastage_Factors | B11: Default / min / max wastage per material class.
A12: Input_Dictionary | B12: Every parameter the AI extraction must produce or the user must confirm, with defaults, validation ranges and sample values.
A13: Element_Library | B13: Drawing elements the AI must detect, which attributes to extract and which work items they drive.
... A24: Key rules | B24: 1) Never invent quantities - missing inputs are flagged. 2) AI extracts, deterministic engine calculates. 3) Every quantity traceable to a drawing element + rule + coefficient. 4) User verifies low-confidence items before BOQ export.
A25: Counts | B25: ="Materials: "&(COUNTA(Material_Master!A:A)-1)&" | Work items: "&(COUNTA(Work_Items!A:A)-1)&" | Recipe lines: "&(COUNTA(Recipes!A:A)-1)&" | Coefficients: "&(COUNTA(Coefficients!A:A)-1) -> Materials: 309 | Work items: 101 | Recipe lines: 308 | Coefficients: 238
A26: Disclaimer | B26: Coefficients marked 'Allowance' are estimating defaults and must be calibrated; structural quantities require an engineer's design/BBS. Not a substitute for professional design.

Sheet Material_Master
A1: Mat_ID | B1: Category | C1: Subcategory | D1: Material Description | E1: Specification/Grade | F1: Unit | G1: Typical Application | H1: Calculation Basis/Formula | I1: Required Inputs | J1: Notes | K1: Scope | L1: Standard/Reference | M1: Takeoff Unit | N1: Formula_Key | O1: Linked Work Items | P1: Wastage_Key | Q1: Wastage % | R1: Construction Stage | S1: Tier/Option | T1: In Sample Drawings? | U1: Drawing Source | V1: Legacy App Code
A2: PRE-001 | B2: Preliminaries & Site | C2: Temporary works | D2: Site hoarding / temporary enclosure | E2: GI corrugated sheet 26-28 SWG on timber/pipe posts, or tarpaulin | F2: rft | G2: Open plot sides, safety & material security | H2: Q = open boundary length (plot perimeter - shared walls - existing walls) | I2: SITE_W, SITE_D, BOUNDARY_LEN | J2: Often omitted in estimates; reusable - consider hire. | K2: Complete | L2: - | M2: rft | N2: LEN(site.open_boundary) | P2: W_NIL | Q2: =IFERROR(INDEX(Wastage_Factors!$B$2:$B$60,MATCH(P2,Wastage_Factors!$A$2:$A$60,0)),0) -> 0 | R2: S0 | S2: Optional | T2: Not shown | U2: Site plan (sh.1)
A3: PRE-002 | B3: Preliminaries & Site | C3: Temporary services | D3: Temporary electricity connection & site DB | E3: IESCO temporary connection; site DB with RCCB | F3: LS | G3: Construction power (mixer, vibrator, lighting) | H3: 1 per project | I3: - | J3: Utility fees are statutory - verify with IESCO. | K3: Complete | L3: PETSAC-2014 | M3: LS | N3: LS | P3: W_NIL | Q3: =IFERROR(INDEX(Wastage_Factors!$B$2:$B$60,MATCH(P3,Wastage_Factors!$A$2:$A$60,0)),0) -> 0 | R3: S0 | S3: Standard | T3: Not shown | U3: -
A4: PRE-003 | B4: Preliminaries & Site | C4: Temporary services | D4: Site store, watchman shed & toilet | E4: Brick/steel temporary shed | F4: LS | G4: Material storage (cement must be kept dry) | H4: 1 per project | I4: - | K4: Complete | L4: - | M4: LS | N4: LS | P4: W_NIL | Q4: =IFERROR(INDEX(Wastage_Factors!$B$2:$B$60,MATCH(P4,Wastage_Factors!$A$2:$A$60,0)),0) -> 0 | R4: S0 | S4: Standard | T4: Not shown | U4: -
A5: PRE-004 | B5: Preliminaries & Site | C5: Setting out | D5: Setting-out consumables | E5: Lime powder, pegs, string line, profile boards | F5: LS | G5: Layout of foundations & walls | H5: 1 per project | I5: - | K5: Complete | L5: - | M5: LS | N5: LS | P5: W_NIL | Q5: =IFERROR(INDEX(Wastage_Factors!$B$2:$B$60,MATCH(P5,Wastage_Factors!$A$2:$A$60,0)),0) -> 0 | R5: S0 | S5: Standard | T5: Implied | U5: Foundation plan
A6: PRE-005 | B6: Preliminaries & Site | C6: Investigations | D6: Soil investigation (SBC test) | E6: 2 boreholes / test pits, SBC & soil classification | F6: Nos | G6: Confirms footing sizes & founding depth | H6: Min 1-2 per plot | I6: PLOT_MARLA | J6: Foundation drawings assume SBC; none stated. Strongly recommended in Islamabad (variable clay/shale). | K6: Complete | L6: BCP-2021 Ch.18 | M6: Nos | N6: COUNT(1..2) | P6: W_NIL | Q6: =IFERROR(INDEX(Wastage_Factors!$B$2:$B$60,MATCH(P6,Wastage_Factors!$A$2:$A$60,0)),0) -> 0 | R6: S0 | S6: Recommended | T6: Not shown | U6: -
A7: PRE-006 | B7: Preliminaries & Site | C7: Quality testing | D7: Material testing (concrete cubes, rebar tensile, bricks) | E7: Cubes 3 per pour (7/28 day); rebar tensile/bend per lot | F7: Nos | G7: QA/QC | H7: Cubes = 3 x number of pours; rebar tests = 1 per lot/diameter | I7: SLAB_AREA, N_FLOORS | K7: Complete | L7: ASTM C39 / A615 | M7: Nos | N7: COUNT(pours)*3 | P7: W_NIL | Q7: =IFERROR(INDEX(Wastage_Factors!$B$2:$B$60,MATCH(P7,Wastage_Factors!$A$2:$A$60,0)),0) -> 0 | R7: S1 | S7: Recommended | T7: Not shown | U7: -
A8: PRE-007 | B8: Preliminaries & Site | C8: Safety | D8: PPE, safety nets, barricading | E8: Helmets, shoes, harness for roof works, edge protection | F8: LS | G8: Site safety | H8: 1 per project | I8: - | K8: Complete | L8: - | M8: LS | N8: LS | P8: W_NIL | Q8: =IFERROR(INDEX(Wastage_Factors!$B$2:$B$60,MATCH(P8,Wastage_Factors!$A$2:$A$60,0)),0) -> 0 | R8: S0 | S8: Standard | T8: Not shown | U8: -
A9: EW-001 | B9: Earthwork & Site Prep | C9: Excavation | D9: Surplus excavated earth - disposal (tractor trolley loads) | E9: Carted to approved dump | F9: cft | G9: Excavated material not reused | H9: Q = Σ [WI qty × Recipe coefficient] × (1 + Wastage %) — driven by WI-EW-09 (see Recipes) | I9: FDN_STRIP_LEN, FDN_SECTION, FTG_ISO, TANK_* | J9: Loose volume = bank volume x bulking (~1.25). | K9: Structure | L9: - | M9: cft | N9: RECIPE | O9: WI-EW-09 | P9: W_NIL | Q9: =IFERROR(INDEX(Wastage_Factors!$B$2:$B$60,MATCH(P9,Wastage_Factors!$A$2:$A$60,0)),0) -> 0 | R9: S1 | S9: Standard | T9: Implied | U9: Foundation details (sh.14-15)
A10: EW-002 | B10: Earthwork & Site Prep | C10: Filling | D10: Imported earth for plinth filling | E10: Good earth, free of organics, compacted in 6in layers at OMC | F10: cft | G10: Plinth fill between foundation walls up to floor base level | H10: Q = Σ [WI qty × Recipe coefficient] × (1 + Wastage %) — driven by WI-EW-05 (see Recipes) | I10: H_PLINTH, ROOM(GF), T_FLOOR_BUILDUP | J10: Drawing plinth 1'-6" above road; porch level differs. | K10: Structure | L10: - | M10: cft | N10: RECIPE | O10: WI-EW-05 | P10: W_EARTH | Q10: =IFERROR(INDEX(Wastage_Factors!$B$2:$B$60,MATCH(P10,Wastage_Factors!$A$2:$A$60,0)),0) -> 0 | R10: S1 | S10: Standard | T10: Implied | U10: Elevations: plinth 1'-6" (sh.5-7) | V10: PLINTH-FILL-01
A11: EW-003 | B11: Earthwork & Site Prep | C11: Filling | D11: Sand filling under floors (local 'bhal' / kassi sand) | E11: Clean fine sand, watered & compacted | F11: cft | G11: Levelling layer under soling/PCC | H11: Q = Σ [WI qty × Recipe coefficient] × (1 + Wastage %) — driven by WI-EW-06 (see Recipes) | I11: ROOM(GF) | K11: Structure | L11: - | M11: cft | N11: RECIPE | O11: WI-EW-06 | P11: W_SAND | Q11: =IFERROR(INDEX(Wastage_Factors!$B$2:$B$60,MATCH(P11,Wastage_Factors!$A$2:$A$60,0)),0) -> 0.1 | R11: S1 | S11: Standard | T11: Not shown | U11: -
A12: EW-004 | B12: Earthwork & Site Prep | C12: Treatment | D12: Anti-termite chemical | E12: Chlorpyrifos 20% EC or imidacloprid, diluted per label | F12: L | G12: Trench bottoms & sides, plinth fill, under floors | H12: Q = Σ [WI qty × Recipe coefficient] × (1 + Wastage %) — driven by WI-EW-07 (see Recipes) | I12: FDN_STRIP_LEN, ROOM(GF) | J12: Not in drawing set; standard in PK specs. | K12: Structure | L12: Manufacturer label | M12: sft | N12: RECIPE | O12: WI-EW-07 | P12: W_MISC | Q12: =IFERROR(INDEX(Wastage_Factors!$B$2:$B$60,MATCH(P12,Wastage_Factors!$A$2:$A$60,0)),0) -> 0.05 | R12: S1 | S12: Recommended | T12: Not shown | U12: - | V12: AT-01
A13: EW-005 | B13: Earthwork & Site Prep | C13: Dewatering | D13: Dewatering (if water table encountered) | E13: Pump hire | F13: LS | G13: Excavation below water table | H13: Contingent on soil report | I13: Soil report | K13: Structure | L13: - | M13: LS | N13: LS | P13: W_NIL | Q13: =IFERROR(INDEX(Wastage_Factors!$B$2:$B$60,MATCH(P13,Wastage_Factors!$A$2:$A$60,0)),0) -> 0 | R13: S1 | S13: Contingent | T13: Not shown | U13: -
A14: EW-006 | B14: Earthwork & Site Prep | C14: Filling | D14: Brick ballast / khangar for sub-base | E14: Over-burnt brick bats 1.5-2in | F14: cft | G14: Sub-base under porch/driveway where specified | H14: Q = area x thickness x 1.15 × (1 + Wastage %) | I14: PAVING_AREA | K14: Structure | L14: - | M14: cft | N14: AREA(paving)*T | P14: W_AGG | Q14: =IFERROR(INDEX(Wastage_Factors!$B$2:$B$60,MATCH(P14,Wastage_Factors!$A$2:$A$60,0)),0) -> 0.075 | R14: S8 | S14: Optional | T14: Not shown | U14: -
A15: EW-007 | B15: Earthwork & Site Prep | C15: Membranes | D15: Polythene vapour barrier under GF floor | E15: 500-1000 gauge LDPE | F15: sft | G15: Below GF floor PCC | H15: Q = Σ [WI qty × Recipe coefficient] × (1 + Wastage %) — driven by WI-EW-08 (see Recipes) | I15: ROOM(GF) | K15: Structure | L15: - | M15: sft | N15: RECIPE | O15: WI-EW-08 | P15: W_POLY | Q15: =IFERROR(INDEX(Wastage_Factors!$B$2:$B$60,MATCH(P15,Wastage_Factors!$A$2:$A$60,0)),0) -> 0.05 | R15: S1 | S15: Recommended | T15: Not shown | U15: -
A16: CON-001 | B16: Concrete & Aggregates | C16: Binders | D16: Ordinary Portland Cement (OPC) - 50 kg bag | E16: Type I, 42.5 grade; fresh stock (<60 days) | F16: bag | G16: All concrete, mortar, plaster, screeds, DPC, bedding | H16: Q = Σ [WI qty × Recipe coefficient] × (1 + Wastage %) — driven by WI-CN-01, WI-CN-02, WI-CN-03, WI-CN-04, WI-CN-05, WI-CN-06, WI-CN-07, WI-CN-08, WI-CN-09, WI-CN-10, WI-CN-11, WI-CN-12, WI-CN-13, WI-MS-01, WI-MS-02, WI-MS-03, WI-MS-04, WI-MS-06, WI-PL-01, WI-PL-02, WI-PL-03, WI-PL-04, WI-WP-01, WI-WP-02, WI-WP-04, WI-FL-01, WI-FL-02, WI-FL-04, WI-PB-12, WI-PB-13, WI-EX-01 (see Recipes) | I16: All concrete/mortar work items | J16: North-region brands: Bestway, Fauji, DG Khan, Askari, Kohat, Cherat, Maple Leaf, Lucky. Cement is ordered in phases - see Construction Stage. | K16: Structure | L16: PS 232 / ASTM C150 | M16: bag | N16: RECIPE | O16: WI-CN-01, WI-CN-02, WI-CN-03, WI-CN-04, WI-CN-05, WI-CN-06, WI-CN-07, WI-CN-08, WI-CN-09, WI-CN-10, WI-CN-11, WI-CN-12, WI-CN-13, WI-MS-01, WI-MS-02, WI-MS-03, WI-MS-04, WI-MS-06, WI-PL-01, WI-PL-02, WI-PL-03, WI-PL-04, WI-WP-01, WI-WP-02, WI-WP-04, WI-FL-01, WI-FL-02, WI-FL-04, WI-PB-12, WI-PB-13, WI-EX-01 | P16: W_CEM | Q16: =IFERROR(INDEX(Wastage_Factors!$B$2:$B$60,MATCH(P16,Wastage_Factors!$A$2:$A$60,0)),0) -> 0.02 | R16: S1-S6 | S16: Standard | T16: Specified | U16: sh.14-16, 24 | V16: BEAM-CONC-01, COL-CONC-01, DPC-01, FDN-MAS-01, FLR-01, FTG-CONC-01, GF-PCC-01, LINTEL-CONC-01, MAS-01, PCC-01, PLAS-01, PLAS-02, PLAS-03, ROOF-01, SLAB-CONC-01, STAIR-CONC-01, WP-01, WSD-01
A17: CON-002 | B17: Concrete & Aggregates | C17: Binders | D17: Sulphate Resisting Cement (SRC) | E17: ASTM C150 Type V | F17: bag | G17: Foundations, septic tank, UG tank where sulphate/saline soil | H17: Replace CON-001 in substructure items if soil report indicates sulphates × (1 + Wastage %) | I17: Soil report | K17: Structure | L17: ASTM C150 | M17: bag | N17: RECIPE(substitute) | P17: W_CEM | Q17: =IFERROR(INDEX(Wastage_Factors!$B$2:$B$60,MATCH(P17,Wastage_Factors!$A$2:$A$60,0)),0) -> 0.02 | R17: S1 | S17: Contingent | T17: Not shown | U17: -
A18: CON-003 | B18: Concrete & Aggregates | C18: Binders | D18: White cement | E18: White Portland cement | F18: kg | G18: Marble joints, tile grout (economy), pointing | H18: Q = Σ [WI qty × Recipe coefficient] × (1 + Wastage %) — driven by WI-FL-04 (see Recipes) | I18: ROOM | K18: Architecture | L18: - | M18: kg | N18: RECIPE | O18: WI-FL-04 | P18: W_CEM | Q18: =IFERROR(INDEX(Wastage_Factors!$B$2:$B$60,MATCH(P18,Wastage_Factors!$A$2:$A$60,0)),0) -> 0.02 | R18: S6 | S18: Standard | T18: Not shown | U18: - | V18: FLR-01
A19: CON-004 | B19: Concrete & Aggregates | C19: Fine aggregate | D19: Coarse sand for concrete (Lawrencepur) | E19: FM >= 2.5, silt < 3% | F19: cft | G19: RCC, PCC, DPC | H19: Q = Σ [WI qty × Recipe coefficient] × (1 + Wastage %) — driven by WI-CN-01, WI-CN-02, WI-CN-03, WI-CN-04, WI-CN-05, WI-CN-06, WI-CN-07, WI-CN-08, WI-CN-09, WI-CN-10, WI-CN-11, WI-CN-12, WI-CN-13, WI-EX-01 (see Recipes) | I19: Concrete work items | J19: Lawrencepur is the default concrete sand in Islamabad/Rawalpindi. Trucks/trolleys vary in cft - verify load size. | K19: Structure | L19: ASTM C33 | M19: cft | N19: RECIPE | O19: WI-CN-01, WI-CN-02, WI-CN-03, WI-CN-04, WI-CN-05, WI-CN-06, WI-CN-07, WI-CN-08, WI-CN-09, WI-CN-10, WI-CN-11, WI-CN-12, WI-CN-13, WI-EX-01 | P19: W_SAND | Q19: =IFERROR(INDEX(Wastage_Factors!$B$2:$B$60,MATCH(P19,Wastage_Factors!$A$2:$A$60,0)),0) -> 0.1 | R19: S1-S3 | S19: Standard | T19: Implied | U19: - | V19: BEAM-CONC-01, COL-CONC-01, DPC-01, FTG-CONC-01, GF-PCC-01, LINTEL-CONC-01, PCC-01, SLAB-CONC-01, STAIR-CONC-01
A20: CON-005 | B20: Concrete & Aggregates | C20: Fine aggregate | D20: Sand for masonry & plaster | E20: Screened, FM 1.8-2.5, clean | F20: cft | G20: Brick mortar, plaster, tile bedding, screeds | H20: Q = Σ [WI qty × Recipe coefficient] × (1 + Wastage %) — driven by WI-MS-01, WI-MS-02, WI-MS-03, WI-MS-04, WI-MS-05, WI-MS-06, WI-PL-01, WI-PL-02, WI-PL-03, WI-PL-04, WI-WP-01, WI-WP-02, WI-WP-04, WI-FL-01, WI-FL-02, WI-FL-04, WI-PB-12, WI-PB-13, WI-EX-01 (see Recipes) | I20: Masonry/plaster work items | J20: Can be same source as CON-004; separate line allows different pricing (e.g. fine plaster sand). | K20: Structure | L20: ASTM C144 | M20: cft | N20: RECIPE | O20: WI-MS-01, WI-MS-02, WI-MS-03, WI-MS-04, WI-MS-05, WI-MS-06, WI-PL-01, WI-PL-02, WI-PL-03, WI-PL-04, WI-WP-01, WI-WP-02, WI-WP-04, WI-FL-01, WI-FL-02, WI-FL-04, WI-PB-12, WI-PB-13, WI-EX-01 | P20: W_SAND | Q20: =IFERROR(INDEX(Wastage_Factors!$B$2:$B$60,MATCH(P20,Wastage_Factors!$A$2:$A$60,0)),0) -> 0.1 | R20: S1-S6 | S20: Standard | T20: Implied | U20: - | V20: FDN-MAS-01, FLR-01, GF-SOL-01, MAS-01, PLAS-01, PLAS-02, PLAS-03, ROOF-01, WP-01, WSD-01
A21: CON-006 | B21: Concrete & Aggregates | C21: Coarse aggregate | D21: Crushed stone 3/4in down (Margalla crush) | E21: Graded 3/4in-#4, clean, angular | F21: cft | G21: RCC footings, columns, beams, slabs, tanks | H21: Q = Σ [WI qty × Recipe coefficient] × (1 + Wastage %) — driven by WI-CN-03, WI-CN-04, WI-CN-05, WI-CN-06, WI-CN-07, WI-CN-08, WI-CN-11 (see Recipes) | I21: Concrete work items | J21: Margalla crush is local to Islamabad; Sargodha crush alternative. | K21: Structure | L21: ASTM C33 | M21: cft | N21: RECIPE | O21: WI-CN-03, WI-CN-04, WI-CN-05, WI-CN-06, WI-CN-07, WI-CN-08, WI-CN-11 | P21: W_AGG | Q21: =IFERROR(INDEX(Wastage_Factors!$B$2:$B$60,MATCH(P21,Wastage_Factors!$A$2:$A$60,0)),0) -> 0.075 | R21: S1-S3 | S21: Standard | T21: Implied | U21: - | V21: BEAM-CONC-01, COL-CONC-01, FTG-CONC-01, SLAB-CONC-01, STAIR-CONC-01
A22: CON-007 | B22: Concrete & Aggregates | C22: Coarse aggregate | D22: Crushed stone 1/2in / 3/8in down | E22: Graded | F22: cft | G22: DPC, lintels, chajjas, apron, thin sections | H22: Q = Σ [WI qty × Recipe coefficient] × (1 + Wastage %) — driven by WI-CN-09, WI-CN-10, WI-CN-12, WI-CN-13 (see Recipes) | I22: DPC, lintels | K22: Structure | L22: ASTM C33 | M22: cft | N22: RECIPE | O22: WI-CN-09, WI-CN-10, WI-CN-12, WI-CN-13 | P22: W_AGG | Q22: =IFERROR(INDEX(Wastage_Factors!$B$2:$B$60,MATCH(P22,Wastage_Factors!$A$2:$A$60,0)),0) -> 0.075 | R22: S1-S2 | S22: Standard | T22: Implied | U22: sh.14 | V22: DPC-01, LINTEL-CONC-01
A23: CON-008 | B23: Concrete & Aggregates | C23: Coarse aggregate | D23: Crushed stone 1.5in down (or brick ballast) | E23: For lean concrete | F23: cft | G23: PCC 1:4:8 foundation base, floor base, manholes | H23: Q = Σ [WI qty × Recipe coefficient] × (1 + Wastage %) — driven by WI-CN-01, WI-CN-02, WI-PB-12, WI-PB-13, WI-EX-01 (see Recipes) | I23: PCC work items | K23: Structure | L23: - | M23: cft | N23: RECIPE | O23: WI-CN-01, WI-CN-02, WI-PB-12, WI-PB-13, WI-EX-01 | P23: W_AGG | Q23: =IFERROR(INDEX(Wastage_Factors!$B$2:$B$60,MATCH(P23,Wastage_Factors!$A$2:$A$60,0)),0) -> 0.075 | R23: S1 | S23: Standard | T23: Specified | U23: sh.14-16, 24 | V23: GF-PCC-01, PCC-01, WSD-01
A24: CON-009 | B24: Concrete & Aggregates | C24: Ready-mix | D24: Ready-mix concrete (alternative to site mix) | E24: 3000-4000 psi, slump per element | F24: cft | G24: Roof/floor slabs where access allows | H24: Q = RCC volume of selected elements x (1 + wastage); replaces CON-001/004/006 for those elements | I24: SLAB_AREA, T_SLAB | J24: Pump charges extra; streets in 5-marla sectors may limit truck access. | K24: Structure | L24: ASTM C94 | M24: m3 | N24: VOL(slab)*(1+w) | P24: W_CONC_RMC | Q24: =IFERROR(INDEX(Wastage_Factors!$B$2:$B$60,MATCH(P24,Wastage_Factors!$A$2:$A$60,0)),0) -> 0.03 | R24: S2 | S24: Optional | T24: Not shown | U24: -
A25: CON-010 | B25: Concrete & Aggregates | C25: Admixtures | D25: Plasticizer / superplasticizer | E25: ASTM C494 Type A/F | F25: L | G25: Slabs/columns for workability at low w/c | H25: Q = cement bags in RCC x dosage (typ. 0.25-0.5 L/bag) × (1 + Wastage %) | I25: Cement qty (RCC) | K25: Structure | L25: ASTM C494 | M25: L | N25: RECIPE(cement_RCC)*dose | P25: W_MISC | Q25: =IFERROR(INDEX(Wastage_Factors!$B$2:$B$60,MATCH(P25,Wastage_Factors!$A$2:$A$60,0)),0) -> 0.05 | R25: S2 | S25: Optional | T25: Not shown | U25: -
A26: CON-011 | B26: Concrete & Aggregates | C26: Admixtures | D26: Bonding agent (SBR latex) | E26: SBR emulsion | F26: L | G26: Plaster on RCC surfaces, repairs, cold joints | H26: Q = RCC exposed area to be plastered x 0.01 L/sft × (1 + Wastage %) | I26: SLAB_AREA | K26: Structure | L26: - | M26: sft | N26: AREA(rcc_soffit)*0.01 | P26: W_MISC | Q26: =IFERROR(INDEX(Wastage_Factors!$B$2:$B$60,MATCH(P26,Wastage_Factors!$A$2:$A$60,0)),0) -> 0.05 | R26: S5 | S26: Optional | T26: Not shown | U26: -
A27: CON-012 | B27: Concrete & Aggregates | C27: Curing | D27: Curing hessian / curing compound | E27: Jute hessian or wax-based compound | F27: sft | G27: Slabs, columns curing (7-14 days) | H27: Q = slab area x 1.1 (reused) × (1 + Wastage %) | I27: SLAB_AREA | K27: Structure | L27: ASTM C309 | M27: sft | N27: AREA(slab)*1.1/reuse | P27: W_MISC | Q27: =IFERROR(INDEX(Wastage_Factors!$B$2:$B$60,MATCH(P27,Wastage_Factors!$A$2:$A$60,0)),0) -> 0.05 | R27: S2 | S27: Standard | T27: Not shown | U27: -
A28: CON-013 | B28: Concrete & Aggregates | C28: Accessories | D28: Cover blocks / rebar spacers | E28: Concrete or PVC, 3/4in slabs, 1.5in beams/cols, 3in footings | F28: Nos | G28: Maintain concrete cover | H28: Q = Σ [WI qty × Recipe coefficient] × (1 + Wastage %) — driven by WI-CN-03, WI-CN-04, WI-CN-05, WI-CN-06, WI-CN-07, WI-CN-08, WI-CN-09 (see Recipes) | I28: RCC work items | K28: Structure | L28: ACI 318 cover | M28: Nos | N28: RECIPE | O28: WI-CN-03, WI-CN-04, WI-CN-05, WI-CN-06, WI-CN-07, WI-CN-08, WI-CN-09 | P28: W_MISC | Q28: =IFERROR(INDEX(Wastage_Factors!$B$2:$B$60,MATCH(P28,Wastage_Factors!$A$2:$A$60,0)),0) -> 0.05 | R28: S1-S2 | S28: Standard | T28: Not shown | U28: - | V28: BEAM-CONC-01, COL-CONC-01, FTG-CONC-01, LINTEL-CONC-01, SLAB-CONC-01, STAIR-CONC-01
A29: CON-014 | B29: Concrete & Aggregates | C29: Aggregate | D29: Stone/marble chips 1/8-3/8in | E29: Topping (drawing: 1.5in chips) | F29: cft | G29: Tank base topping, terrazzo/chips flooring | H29: Q = area x thickness x dry factor 1.3 × (1 + Wastage %) | I29: TANK_UG | J29: Drawing notes '1.5in thick chips' in UG/septic tank details. | K29: Structure | L29: - | M29: sft | N29: AREA*T*1.3 | P29: W_AGG | Q29: =IFERROR(INDEX(Wastage_Factors!$B$2:$B$60,MATCH(P29,Wastage_Factors!$A$2:$A$60,0)),0) -> 0.075 | R29: S1 | S29: Standard | T29: Specified | U29: Tanks detail (sh.16)
A30: RBR-001 | B30: Reinforcement & Steel | C30: Rebar | D30: Deformed bar #3 (10 mm / 3/8in) | E30: ASTM A615 Grade 60 (fy 60,000 psi / 420 MPa); 0.56 kg/m | F30: kg | G30: Ties/stirrups, slab distribution, tank walls (3/8in @6in c/c per drawing) | H30: Q = Σ [WI qty × Recipe coefficient] × (1 + Wastage %) — driven by WI-RF-01, WI-RF-02, WI-RF-03, WI-RF-04, WI-RF-05, WI-RF-06, WI-RF-07 (see Recipes) | I30: BBS or member volumes + K_ST ratios | J30: Mills: Amreli, Mughal, Ittehad, Naveena, Agha, AFCO. Standard length 12 m (40 ft). Purchase in tons. | K30: Structure | L30: ASTM A615 Gr60 | M30: kg | N30: RECIPE | O30: WI-RF-01, WI-RF-02, WI-RF-03, WI-RF-04, WI-RF-05, WI-RF-06, WI-RF-07 | P30: W_STEEL | Q30: =IFERROR(INDEX(Wastage_Factors!$B$2:$B$60,MATCH(P30,Wastage_Factors!$A$2:$A$60,0)),0) -> 0.03 | R30: S1-S2 | S30: Standard | T30: Specified | U30: sh.14, 16 | V30: BEAM-STEEL-01, COL-STEEL-01, FTG-STEEL-01, LINTEL-STEEL-01, SLAB-STEEL-01, STAIR-STEEL-01
A31: RBR-002 | B31: Reinforcement & Steel | C31: Rebar | D31: Deformed bar #4 (12 mm / 1/2in) | E31: ASTM A615 Gr60; 0.99 kg/m | F31: kg | G31: Slab main bars, column/beam bars, footing mats | H31: Q = Σ [WI qty × Recipe coefficient] × (1 + Wastage %) — driven by WI-RF-01, WI-RF-02, WI-RF-03, WI-RF-04, WI-RF-05, WI-RF-06, WI-PB-12 (see Recipes) | I31: BBS | K31: Structure | L31: ASTM A615 Gr60 | M31: kg | N31: RECIPE | O31: WI-RF-01, WI-RF-02, WI-RF-03, WI-RF-04, WI-RF-05, WI-RF-06, WI-PB-12 | P31: W_STEEL | Q31: =IFERROR(INDEX(Wastage_Factors!$B$2:$B$60,MATCH(P31,Wastage_Factors!$A$2:$A$60,0)),0) -> 0.03 | R31: S1-S2 | S31: Standard | T31: Specified | U31: sh.14 (sec AA #4) | V31: BEAM-STEEL-01, COL-STEEL-01, FTG-STEEL-01, LINTEL-STEEL-01, SLAB-STEEL-01, STAIR-STEEL-01, WSD-01
A32: RBR-003 | B32: Reinforcement & Steel | C32: Rebar | D32: Deformed bar #5 (16 mm / 5/8in) | E32: ASTM A615 Gr60; 1.58 kg/m | F32: kg | G32: Beam & column main bars | H32: Q = Σ [WI qty × Recipe coefficient] × (1 + Wastage %) — driven by WI-RF-02, WI-RF-03 (see Recipes) | I32: BBS | J32: No beam/column schedule in drawing set - quantity from ratio only until structural drawings are issued. | K32: Structure | L32: ASTM A615 Gr60 | M32: kg | N32: RECIPE | O32: WI-RF-02, WI-RF-03 | P32: W_STEEL | Q32: =IFERROR(INDEX(Wastage_Factors!$B$2:$B$60,MATCH(P32,Wastage_Factors!$A$2:$A$60,0)),0) -> 0.03 | R32: S2 | S32: Standard | T32: Not shown | U32: Not detailed | V32: BEAM-STEEL-01, COL-STEEL-01
A33: RBR-004 | B33: Reinforcement & Steel | C33: Rebar | D33: Deformed bar #6 (19/20 mm / 3/4in) | E33: ASTM A615 Gr60; 2.24 kg/m | F33: kg | G33: Longer-span beams, 10-marla columns, cantilevers | H33: Q = BBS kg for #6 bars x (1 + w) | I33: BBS | K33: Structure | L33: ASTM A615 Gr60 | M33: kg | N33: BBS(#6) | P33: W_STEEL | Q33: =IFERROR(INDEX(Wastage_Factors!$B$2:$B$60,MATCH(P33,Wastage_Factors!$A$2:$A$60,0)),0) -> 0.03 | R33: S2 | S33: Contingent | T33: Not shown | U33: Not detailed
A34: RBR-006 | B34: Reinforcement & Steel | C34: Accessories | D34: Binding wire (black annealed) | E34: 18/20 SWG | F34: kg | G34: Tying all reinforcement | H34: Q = Σ [WI qty × Recipe coefficient] × (1 + Wastage %) — driven by WI-RF-01, WI-RF-02, WI-RF-03, WI-RF-04, WI-RF-05, WI-RF-06, WI-RF-07 (see Recipes) | I34: Total rebar kg | J34: ~10 kg per tonne of steel. | K34: Structure | L34: - | M34: kg | N34: RECIPE | O34: WI-RF-01, WI-RF-02, WI-RF-03, WI-RF-04, WI-RF-05, WI-RF-06, WI-RF-07 | P34: W_NIL | Q34: =IFERROR(INDEX(Wastage_Factors!$B$2:$B$60,MATCH(P34,Wastage_Factors!$A$2:$A$60,0)),0) -> 0 | R34: S1-S2 | S34: Standard | T34: Implied | U34: - | V34: BEAM-STEEL-01, COL-STEEL-01, FTG-STEEL-01, LINTEL-STEEL-01, SLAB-STEEL-01, STAIR-STEEL-01
A35: RBR-007 | B35: Reinforcement & Steel | C35: Accessories | D35: Chairs / bar supports | E35: Fabricated from #3/#4 bars | F35: kg | G35: Top-mat support in slabs/footings | H35: Q = 1-1.5% of slab + footing steel (if not in BBS) × (1 + Wastage %) | I35: BBS | J35: Usually included in BBS/ratio - avoid double counting. | K35: Structure | L35: - | M35: kg | N35: (WI-RF-01+WI-RF-04)*0.015 | P35: W_STEEL | Q35: =IFERROR(INDEX(Wastage_Factors!$B$2:$B$60,MATCH(P35,Wastage_Factors!$A$2:$A$60,0)),0) -> 0.03 | R35: S2 | S35: Standard | T35: Not shown | U35: -
A36: RBR-008 | B36: Reinforcement & Steel | C36: Mesh | D36: Welded wire mesh | E36: e.g. 6mm @ 6in | F36: sft | G36: Porch/driveway slabs, screed crack control | H36: Q = area x 1.1 (laps) × (1 + Wastage %) | I36: PAVING_AREA | K36: Structure | L36: ASTM A1064 | M36: sft | N36: AREA*1.1 | P36: W_STEEL | Q36: =IFERROR(INDEX(Wastage_Factors!$B$2:$B$60,MATCH(P36,Wastage_Factors!$A$2:$A$60,0)),0) -> 0.03 | R36: S8 | S36: Optional | T36: Not shown | U36: -
A37: RBR-009 | B37: Reinforcement & Steel | C37: Structural steel | D37: MS sections (angles, channels, pipes, flats) | E37: ASTM A36 / local MS | F37: kg | G37: Tank stand, canopy frames, gate frame, manhole frames | H37: Q = sum(member length x unit weight) from details × (1 + Wastage %) | I37: Details | J37: Manhole cover frames specified as 2x2x1/4in angle; 2.5x2.5x1/2in CI angle frame. | K37: Structure | L37: ASTM A36 | M37: kg | N37: SUM(len*kg_m) | P37: W_STEEL_SECT | Q37: =IFERROR(INDEX(Wastage_Factors!$B$2:$B$60,MATCH(P37,Wastage_Factors!$A$2:$A$60,0)),0) -> 0.05 | R37: S2-S8 | S37: Standard | T37: Specified | U37: sh.24 (2x2x1/4 angle frames)
A38: RBR-010 | B38: Reinforcement & Steel | C38: Seismic | D38: Wall ties / dowels at column-wall & wall-wall junctions | E38: #3 bar 2ft long every 4th course, or GI hoop iron | F38: kg | G38: Tie masonry to RCC columns; seismic zone 2B | H38: Q = junction count x (wall height / 1ft) / 4 x 0.61 m x 0.56 kg/m × (1 + Wastage %) | I38: WALL_CL_LEN, COL | J38: Islamabad/Rawalpindi are seismic zone 2B (BCP SP-2007 Table 2.2). | K38: Structure | L38: BCP-2021 masonry provisions | M38: kg | N38: COUNT(junctions)*H/1*0.25*0.34 | P38: W_STEEL | Q38: =IFERROR(INDEX(Wastage_Factors!$B$2:$B$60,MATCH(P38,Wastage_Factors!$A$2:$A$60,0)),0) -> 0.03 | R38: S2 | S38: Recommended | T38: Not shown | U38: Not shown
A39: FRM-001 | B39: Formwork & Temporary Works | C39: Shuttering | D39: Steel shuttering plates (hire) | E39: Steel plates on props | F39: sft | G39: Slab & beam soffits | H39: Q = Σ [WI qty × Recipe coefficient] × (1 + Wastage %) — driven by WI-FW-01 (see Recipes) | I39: SLAB_AREA, BEAM | J39: Commonly hired per sft per cast in PK. | K39: Structure | L39: - | M39: sft | N39: RECIPE | O39: WI-FW-01 | P39: W_NIL | Q39: =IFERROR(INDEX(Wastage_Factors!$B$2:$B$60,MATCH(P39,Wastage_Factors!$A$2:$A$60,0)),0) -> 0 | R39: S2 | S39: Standard | T39: Not shown | U39: - | V39: FORM-SLAB-01
A40: FRM-002 | B40: Formwork & Temporary Works | C40: Shuttering | D40: Plywood (shuttering grade 12-18mm) / timber planks | E40: Film-faced or commercial ply | F40: sft | G40: Columns, footings, lintels, stairs, tanks | H40: Q = Σ [WI qty × Recipe coefficient] × (1 + Wastage %) — driven by WI-FW-02 (see Recipes) | I40: Contact areas | K40: Structure | L40: - | M40: sft | N40: RECIPE | O40: WI-FW-02 | P40: W_WOOD_BOARD | Q40: =IFERROR(INDEX(Wastage_Factors!$B$2:$B$60,MATCH(P40,Wastage_Factors!$A$2:$A$60,0)),0) -> 0.1 | R40: S1-S2 | S40: Standard | T40: Not shown | U40: - | V40: FORM-COL-01
...

Sheet Work_Items
A1: WI_ID | B1: Scope | C1: Division | D1: Work Item Description | E1: Unit (FPS) | F1: Unit (SI) | G1: Measurement Rule | H1: Quantity Formula (engine expression) | I1: Required Inputs | J1: Default Specification | K1: Legacy App Code | L1: No. of Recipe Lines
A2: WI-PRE-01 | B2: Complete | C2: Preliminaries | D2: Site clearance, setting out & temporary works | E2: LS | F2: LS | G2: Lump sum per project | H2: LS | I2: SITE_W, SITE_D | J2: Hoarding, store, temporary water/electricity | K2: PRELIM-01 | L2: =COUNTIF(Recipes!$A$2:$A$1000,A2) -> 0
A3: WI-PRE-02 | B3: Complete | C3: Preliminaries | D3: Construction water (tanker / bore) | E3: gal | F3: L | G3: Derived from total cement consumption | H3: SUM(cement_bags) * K_WATER_L_BAG / 4.546 | I3: All concrete/mortar work items | J3: Tanker water if no CDA/bore supply | L3: =COUNTIF(Recipes!$A$2:$A$1000,A3) -> 1
A4: WI-EW-01 | B4: Structure | C4: Earthwork | D4: Excavation for strip foundations | E4: cft | F4: m3 | G4: Trench length along wall centreline x (bottom width of PCC + 2 x working space) x depth below NSL; no deduction for pipes <6in | H4: SUM(strip.len_cl * (strip.pcc_w + 2*P_WORKSPACE) * strip.depth) | I4: FDN_STRIP_LEN, FDN_SECTION, FDN_DEPTH | J4: Ordinary soil | K4: EXC-01 | L4: =COUNTIF(Recipes!$A$2:$A$1000,A4) -> 0
A5: WI-EW-02 | B5: Structure | C5: Earthwork | D5: Excavation for isolated column footings | E5: cft | F5: m3 | G5: (L+2ws) x (B+2ws) x D per footing x count | H5: SUM(ftg.n * (ftg.L+2*P_WORKSPACE)*(ftg.B+2*P_WORKSPACE)*ftg.D) | I5: FTG_ISO | K5: EXC-01 | L5: =COUNTIF(Recipes!$A$2:$A$1000,A5) -> 0
A6: WI-EW-03 | B6: Plumbing | C6: Earthwork | D6: Excavation for tanks, septic, manholes, sewer trenches | E6: cft | F6: m3 | G6: External plan dims + working space x depth; trench = length x 2ft x avg depth | H6: SUM(tank.ext_L*tank.ext_B*tank.D) + sewer.len*2*sewer.avg_depth | I6: TANK_UG, TANK_SEPTIC, SEWER_EXT_LEN, MH_COUNT | L6: =COUNTIF(Recipes!$A$2:$A$1000,A6) -> 0
A7: WI-EW-04 | B7: Structure | C7: Earthwork | D7: Backfill with excavated earth, compacted in 6in layers | E7: cft | F7: m3 | G7: Excavation minus volume of PCC, footing, masonry below NGL | H7: WI-EW-01 + WI-EW-02 - V(below NGL structures) | I7: Derived | K7: BACKFILL-01 | L7: =COUNTIF(Recipes!$A$2:$A$1000,A7) -> 0
A8: WI-EW-05 | B8: Structure | C8: Earthwork | D8: Plinth filling with imported earth, compacted | E8: cft | F8: m3 | G8: GF internal floor area x (plinth height - floor build-up thickness) | H8: GF.net_floor_area * (H_PLINTH - T_FLOOR_BUILDUP) | I8: H_PLINTH, ROOM (GF), T_FLOOR_BUILDUP | J8: Good earth free of organics | K8: PLINTH-FILL-01 | L8: =COUNTIF(Recipes!$A$2:$A$1000,A8) -> 1
A9: WI-EW-06 | B9: Structure | C9: Earthwork | D9: Sand filling under floors | E9: cft | F9: m3 | G9: GF floor area x sand thickness | H9: GF.net_floor_area * P_SAND_FILL_T | I9: ROOM (GF) | J9: 3-4 in | L9: =COUNTIF(Recipes!$A$2:$A$1000,A9) -> 1
A10: WI-EW-07 | B10: Structure | C10: Earthwork | D10: Anti-termite treatment (foundation trenches, plinth, floor) | E10: sft | F10: m2 | G10: Trench bottom+sides area + plinth fill surface | H10: WI-EW-01 surfaces + GF.floor_area | I10: Derived | J10: Chlorpyrifos/imidacloprid emulsion per label | K10: AT-01 | L10: =COUNTIF(Recipes!$A$2:$A$1000,A10) -> 1
A11: WI-EW-08 | B11: Structure | C11: Earthwork | D11: Polythene vapour barrier under GF floor PCC | E11: sft | F11: m2 | G11: GF floor area | H11: GF.net_floor_area | I11: ROOM (GF) | J11: 500-1000 gauge | L11: =COUNTIF(Recipes!$A$2:$A$1000,A11) -> 1
A12: WI-EW-09 | B12: Structure | C12: Earthwork | D12: Disposal of surplus earth | E12: cft | F12: m3 | G12: Excavation - backfill reused (loose) | H12: (WI-EW-01+WI-EW-02+WI-EW-03-WI-EW-04) * P_BULKING | I12: Derived | L12: =COUNTIF(Recipes!$A$2:$A$1000,A12) -> 1
A13: WI-CN-01 | B13: Structure | C13: Concrete | D13: PCC 1:4:8 in foundation base | E13: cft | F13: m3 | G13: Strip: length x PCC width x thickness; isolated: (L+2p)(B+2p)t | H13: SUM(strip.len_cl*strip.pcc_w*strip.pcc_t) + SUM(ftg.n*(ftg.L+2p)*(ftg.B+2p)*t) | I13: FDN_SECTION, FTG_ISO | J13: Drawing: PCC 1:4:8 | K13: PCC-01 | L13: =COUNTIF(Recipes!$A$2:$A$1000,A13) -> 3
A14: WI-CN-02 | B14: Structure | C14: Concrete | D14: PCC 1:4:8 floor base (GF, porch) | E14: cft | F14: m3 | G14: Floor area x thickness | H14: GF.net_floor_area * P_FLOOR_PCC_T | I14: ROOM (GF), PORCH | J14: 3 in | K14: GF-PCC-01 | L14: =COUNTIF(Recipes!$A$2:$A$1000,A14) -> 3
A15: WI-CN-03 | B15: Structure | C15: Concrete | D15: RCC 1:2:4 in isolated footings | E15: cft | F15: m3 | G15: n x L x B x D (+ pedestal) | H15: SUM(ftg.n*ftg.L*ftg.B*ftg.D) | I15: FTG_ISO | J15: Drawing C1 4x4, C2/C3 3x3 | K15: FTG-CONC-01 | L15: =COUNTIF(Recipes!$A$2:$A$1000,A15) -> 4
A16: WI-CN-04 | B16: Structure | C16: Concrete | D16: RCC in plinth / grade beams | E16: cft | F16: m3 | G16: Length x b x d | H16: SUM(pb.len*pb.b*pb.d) | I16: PLINTH_BEAM | J16: If specified (not in sample) | L16: =COUNTIF(Recipes!$A$2:$A$1000,A16) -> 4
A17: WI-CN-05 | B17: Structure | C17: Concrete | D17: RCC in columns | E17: cft | F17: m3 | G17: n x b x d x height (footing top to roof) | H17: SUM(col.n*col.b*col.d*col.h) | I17: COL | J17: C1 9x18, C2/C3 15x15 | K17: COL-CONC-01 | L17: =COUNTIF(Recipes!$A$2:$A$1000,A17) -> 4
A18: WI-CN-06 | B18: Structure | C18: Concrete | D18: RCC in beams (below slab soffit) | E18: cft | F18: m3 | G18: Length (clear) x b x (D - slab t) | H18: SUM(beam.len*beam.b*(beam.D-T_SLAB)) | I18: BEAM | K18: BEAM-CONC-01 | L18: =COUNTIF(Recipes!$A$2:$A$1000,A18) -> 4
A19: WI-CN-07 | B19: Structure | C19: Concrete | D19: RCC in floor & roof slabs | E19: cft | F19: m3 | G19: Slab area (outer face of bearing walls) - voids (stair, shafts) x thickness; per floor | H19: SUM(slab.area - slab.voids) * T_SLAB | I19: SLAB_AREA, SLAB_VOID, T_SLAB | J19: 6 in per elevations | K19: SLAB-CONC-01 | L19: =COUNTIF(Recipes!$A$2:$A$1000,A19) -> 4
A20: WI-CN-08 | B20: Structure | C20: Concrete | D20: RCC in staircase (waist, steps, landings) | E20: cft | F20: m3 | G20: Waist: inclined length x width x waist t; steps: 0.5 x R x G x width x n; landings: area x t | H20: stair.waist + stair.steps + stair.landings | I20: STAIR | K20: STAIR-CONC-01 | L20: =COUNTIF(Recipes!$A$2:$A$1000,A20) -> 4
A21: WI-CN-09 | B21: Structure | C21: Concrete | D21: RCC lintels & seismic bands (lintel/roof/sill) | E21: cft | F21: m3 | G21: Lintel: (opening W + 2 x bearing 9in) x wall t x depth; bands: wall centreline length x t x depth | H21: SUM(opening.W+2*P_BEARING)*t*d + SUM(wall.len_cl)*t*band_d | I21: WALL_CL_LEN, OPENINGS, BAND_LEN | J21: Recommend continuous bands (zone 2B) | K21: LINTEL-CONC-01 | L21: =COUNTIF(Recipes!$A$2:$A$1000,A21) -> 4
A22: WI-CN-10 | B22: Structure | C22: Concrete | D22: RCC chajjas, projections, balcony slabs, canopies | E22: cft | F22: m3 | G22: Length x projection x avg thickness | H22: SUM(proj.len*proj.w*proj.t) | I22: ELEVATIONS, BALCONY | L22: =COUNTIF(Recipes!$A$2:$A$1000,A22) -> 3
A23: WI-CN-11 | B23: Plumbing | C23: Concrete | D23: RCC in UG water tank / septic tank (base, walls, cover) | E23: cft | F23: m3 | G23: Base + walls (centreline perimeter x t x h) + cover slab - openings | H23: tank.base + tank.walls + tank.cover | I23: TANK_UG, TANK_SEPTIC | J23: Drawing: RCC 1:2:4, 6in walls, 4in slab | L23: =COUNTIF(Recipes!$A$2:$A$1000,A23) -> 4
A24: WI-CN-12 | B24: Structure | C24: Concrete | D24: DPC 1.5in PCC 1:2:4 with WP admixture, bitumen & polythene | E24: sft | F24: m2 | G24: Length of all walls at plinth x wall thickness (no deduction for door openings unless specified) | H24: SUM(wall_GF.len_cl * wall.t) | I24: WALL_CL_LEN (GF) | J24: Drawing sheet 14/15 | K24: DPC-01 | L24: =COUNTIF(Recipes!$A$2:$A$1000,A24) -> 6
A25: WI-CN-13 | B25: External | C25: Concrete | D25: Plinth protection / apron PCC 1:2:4 3in | E25: sft | F25: m2 | G25: External perimeter x apron width | H25: ext_perimeter * P_APRON_W | I25: Building footprint | J25: 2-3 ft wide | L25: =COUNTIF(Recipes!$A$2:$A$1000,A25) -> 3
A26: WI-RF-01 | B26: Structure | C26: Reinforcement | D26: Reinforcement in footings | E26: kg | F26: kg | G26: BBS if available; else V_footing x ratio | H26: BBS or WI-CN-03 * K_ST_FTG | I26: FTG_ISO / BBS | J26: ASTM A615 Gr60 | K26: FTG-STEEL-01 | L26: =COUNTIF(Recipes!$A$2:$A$1000,A26) -> 3
A27: WI-RF-02 | B27: Structure | C27: Reinforcement | D27: Reinforcement in columns | E27: kg | F27: kg | G27: BBS; else V x ratio (incl. laps, ties) | H27: BBS or WI-CN-05 * K_ST_COL | I27: COL / BBS | K27: COL-STEEL-01 | L27: =COUNTIF(Recipes!$A$2:$A$1000,A27) -> 4
A28: WI-RF-03 | B28: Structure | C28: Reinforcement | D28: Reinforcement in beams & plinth beams | E28: kg | F28: kg | G28: BBS; else V x ratio | H28: BBS or (WI-CN-06*K_ST_BEAM + WI-CN-04*K_ST_PB) | I28: BEAM / BBS | K28: BEAM-STEEL-01 | L28: =COUNTIF(Recipes!$A$2:$A$1000,A28) -> 4
A29: WI-RF-04 | B29: Structure | C29: Reinforcement | D29: Reinforcement in slabs | E29: kg | F29: kg | G29: BBS; else V x ratio | H29: BBS or WI-CN-07 * K_ST_SLAB | I29: SLAB / BBS | K29: SLAB-STEEL-01 | L29: =COUNTIF(Recipes!$A$2:$A$1000,A29) -> 3
A30: WI-RF-05 | B30: Structure | C30: Reinforcement | D30: Reinforcement in stairs | E30: kg | F30: kg | G30: BBS; else V x ratio | H30: BBS or WI-CN-08 * K_ST_STAIR | I30: STAIR / BBS | K30: STAIR-STEEL-01 | L30: =COUNTIF(Recipes!$A$2:$A$1000,A30) -> 3
A31: WI-RF-06 | B31: Structure | C31: Reinforcement | D31: Reinforcement in lintels, bands, chajjas | E31: kg | F31: kg | G31: BBS; else V x ratio | H31: BBS or (WI-CN-09+WI-CN-10) * K_ST_LINTEL | I31: BBS | K31: LINTEL-STEEL-01 | L31: =COUNTIF(Recipes!$A$2:$A$1000,A31) -> 3
A32: WI-RF-07 | B32: Plumbing | C32: Reinforcement | D32: Reinforcement in tanks (3/8in @ 6-12in c/c both faces) | E32: kg | F32: kg | G32: BBS from tank detail; else V x ratio | H32: BBS or WI-CN-11 * K_ST_TANK | I32: TANK details | J32: Drawing sheet 16 | L32: =COUNTIF(Recipes!$A$2:$A$1000,A32) -> 2
A33: WI-FW-01 | B33: Structure | C33: Formwork | D33: Formwork to slabs & beam soffits (steel shuttering, hired) | E33: sft | F33: m2 | G33: Soffit area + beam sides | H33: SUM(slab.area) + SUM(beam.len*2*(beam.D-T_SLAB)) | I33: SLAB_AREA, BEAM | K33: FORM-SLAB-01 | L33: =COUNTIF(Recipes!$A$2:$A$1000,A33) -> 4
A34: WI-FW-02 | B34: Structure | C34: Formwork | D34: Formwork to columns, footings, lintels, stairs, tanks (ply/timber) | E34: sft | F34: m2 | G34: Contact area of concrete surfaces | H34: SUM(contact areas) | I34: COL, FTG_ISO, STAIR, TANK, OPENINGS | K34: FORM-COL-01 | L34: =COUNTIF(Recipes!$A$2:$A$1000,A34) -> 4
A35: WI-MS-01 | B35: Structure | C35: Masonry | D35: Brick masonry in stepped foundations 1:6 (below DPC) | E35: cft | F35: m3 | G35: Sum over steps: centreline length x step width x step height; T-junction correction | H35: SUM(strip.len_cl * SUM(step.w*step.h)) | I35: FDN_SECTION, FDN_STRIP_LEN | J35: Drawing sections 1.1-6.6 | K35: FDN-MAS-01 | L35: =COUNTIF(Recipes!$A$2:$A$1000,A35) -> 3
A36: WI-MS-02 | B36: Structure | C36: Masonry | D36: Brick masonry 9in in superstructure 1:6 | E36: cft | F36: m3 | G36: Centreline length x height x 0.75 ft - openings - lintels/bands/columns embedded | H36: SUM(wall9.len_cl*wall.h*0.75) - SUM(openings in 9in walls)*0.75 - V(lintels,bands,cols) | I36: WALL_CL_LEN, WALL_H, OPENINGS | K36: MAS-01 | L36: =COUNTIF(Recipes!$A$2:$A$1000,A36) -> 4
A37: WI-MS-03 | B37: Architecture | C37: Masonry | D37: Brick masonry 4.5in partitions 1:4 | E37: sft | F37: m2 | G37: Length x height - openings | H37: SUM(wall45.len*wall.h) - SUM(openings in 4.5in walls) | I37: WALL_CL_LEN, OPENINGS | K37: MAS-01 | L37: =COUNTIF(Recipes!$A$2:$A$1000,A37) -> 3
A38: WI-MS-04 | B38: Structure | C38: Masonry | D38: Parapet walls 9in / 4.5in | E38: cft | F38: m3 | G38: Roof perimeter x parapet height x t | H38: roof.perimeter * H_PARAPET * t | I38: ROOF_AREA, H_PARAPET | J38: Drawing: 2-3 ft | K38: MAS-01 | L38: =COUNTIF(Recipes!$A$2:$A$1000,A38) -> 3
A39: WI-MS-05 | B39: Structure | C39: Masonry | D39: Brick soling (flat) under GF floors | E39: sft | F39: m2 | G39: GF floor area | H39: GF.net_floor_area | I39: ROOM (GF) | K39: GF-SOL-01 | L39: =COUNTIF(Recipes!$A$2:$A$1000,A39) -> 2
A40: WI-MS-06 | B40: Architecture | C40: Masonry | D40: Concrete block masonry 8in (alternative) | E40: sft | F40: m2 | G40: Length x height - openings | H40: SUM(len*h) - openings | I40: WALL_CL_LEN | J40: Only if specified | L40: =COUNTIF(Recipes!$A$2:$A$1000,A40) -> 3
...

Sheet Recipes
A1: WI_ID | B1: Work Item | C1: Mat_ID | D1: Material | E1: Driver Coeff_ID | F1: Mix_Ref | G1: Mix_Component | H1: Coefficient (material per unit of WI) | I1: Coeff Unit | J1: Basis | K1: Material Unit | L1: Wastage %
A2: WI-PRE-02 | B2: =INDEX(Work_Items!$D$2:$D$300,MATCH(A2,Work_Items!$A$2:$A$300,0)) -> Construction water (tanker / bore) | C2: MSC-001 | D2: =INDEX(Material_Master!$D$2:$D$1000,MATCH(C2,Material_Master!$A$2:$A$1000,0)) -> Construction water (tanker/bore) for mixing & curing | E2: K_ONE | H2: =Coefficients!$D$2 -> 1 | I2: gal/gal | J2: Qty computed in work item | K2: =INDEX(Material_Master!$F$2:$F$1000,MATCH(C2,Material_Master!$A$2:$A$1000,0)) -> gal | L2: =INDEX(Material_Master!$Q$2:$Q$1000,MATCH(C2,Material_Master!$A$2:$A$1000,0)) -> 0
A3: WI-EW-05 | B3: =INDEX(Work_Items!$D$2:$D$300,MATCH(A3,Work_Items!$A$2:$A$300,0)) -> Plinth filling with imported earth, compacted | C3: EW-002 | D3: =INDEX(Material_Master!$D$2:$D$1000,MATCH(C3,Material_Master!$A$2:$A$1000,0)) -> Imported earth for plinth filling | E3: K_FILL_COMPACT | H3: =Coefficients!$D$67 -> 1.2 | I3: cft/cft | J3: Loose imported earth per compacted cft | K3: =INDEX(Material_Master!$F$2:$F$1000,MATCH(C3,Material_Master!$A$2:$A$1000,0)) -> cft | L3: =INDEX(Material_Master!$Q$2:$Q$1000,MATCH(C3,Material_Master!$A$2:$A$1000,0)) -> 0
A4: WI-EW-06 | B4: =INDEX(Work_Items!$D$2:$D$300,MATCH(A4,Work_Items!$A$2:$A$300,0)) -> Sand filling under floors | C4: EW-003 | D4: =INDEX(Material_Master!$D$2:$D$1000,MATCH(C4,Material_Master!$A$2:$A$1000,0)) -> Sand filling under floors (local 'bhal' / kassi sand) | E4: K_SAND_COMPACT | H4: =Coefficients!$D$68 -> 1.15 | I4: cft/cft | K4: =INDEX(Material_Master!$F$2:$F$1000,MATCH(C4,Material_Master!$A$2:$A$1000,0)) -> cft | L4: =INDEX(Material_Master!$Q$2:$Q$1000,MATCH(C4,Material_Master!$A$2:$A$1000,0)) -> 0.1
A5: WI-EW-07 | B5: =INDEX(Work_Items!$D$2:$D$300,MATCH(A5,Work_Items!$A$2:$A$300,0)) -> Anti-termite treatment (foundation trenches, plinth, floor) | C5: EW-004 | D5: =INDEX(Material_Master!$D$2:$D$1000,MATCH(C5,Material_Master!$A$2:$A$1000,0)) -> Anti-termite chemical | E5: K_AT_L_SFT | H5: =Coefficients!$D$69 -> 0.025 | I5: L/sft | J5: Per label | K5: =INDEX(Material_Master!$F$2:$F$1000,MATCH(C5,Material_Master!$A$2:$A$1000,0)) -> L | L5: =INDEX(Material_Master!$Q$2:$Q$1000,MATCH(C5,Material_Master!$A$2:$A$1000,0)) -> 0.05
A6: WI-EW-08 | B6: =INDEX(Work_Items!$D$2:$D$300,MATCH(A6,Work_Items!$A$2:$A$300,0)) -> Polythene vapour barrier under GF floor PCC | C6: EW-007 | D6: =INDEX(Material_Master!$D$2:$D$1000,MATCH(C6,Material_Master!$A$2:$A$1000,0)) -> Polythene vapour barrier under GF floor | E6: K_RF_POLY | H6: =Coefficients!$D$54 -> 1.15 | I6: sft/sft | J6: incl. overlap | K6: =INDEX(Material_Master!$F$2:$F$1000,MATCH(C6,Material_Master!$A$2:$A$1000,0)) -> sft | L6: =INDEX(Material_Master!$Q$2:$Q$1000,MATCH(C6,Material_Master!$A$2:$A$1000,0)) -> 0.05
A7: WI-EW-09 | B7: =INDEX(Work_Items!$D$2:$D$300,MATCH(A7,Work_Items!$A$2:$A$300,0)) -> Disposal of surplus earth | C7: EW-001 | D7: =INDEX(Material_Master!$D$2:$D$1000,MATCH(C7,Material_Master!$A$2:$A$1000,0)) -> Surplus excavated earth - disposal (tractor trolley loads) | E7: K_ONE | H7: =Coefficients!$D$2 -> 1 | I7: cft/cft | K7: =INDEX(Material_Master!$F$2:$F$1000,MATCH(C7,Material_Master!$A$2:$A$1000,0)) -> cft | L7: =INDEX(Material_Master!$Q$2:$Q$1000,MATCH(C7,Material_Master!$A$2:$A$1000,0)) -> 0
A8: WI-CN-01 | B8: =INDEX(Work_Items!$D$2:$D$300,MATCH(A8,Work_Items!$A$2:$A$300,0)) -> PCC 1:4:8 in foundation base | C8: CON-001 | D8: =INDEX(Material_Master!$D$2:$D$1000,MATCH(C8,Material_Master!$A$2:$A$1000,0)) -> Ordinary Portland Cement (OPC) - 50 kg bag | E8: K_ONE | F8: MX_PCC148 | G8: cement | H8: =Coefficients!$D$2*Mix_Design!$J$2 -> 0.096608277 | I8: bag/cft | J8: Mix_Design | K8: =INDEX(Material_Master!$F$2:$F$1000,MATCH(C8,Material_Master!$A$2:$A$1000,0)) -> bag | L8: =INDEX(Material_Master!$Q$2:$Q$1000,MATCH(C8,Material_Master!$A$2:$A$1000,0)) -> 0.02
A9: WI-CN-01 | B9: =INDEX(Work_Items!$D$2:$D$300,MATCH(A9,Work_Items!$A$2:$A$300,0)) -> PCC 1:4:8 in foundation base | C9: CON-004 | D9: =INDEX(Material_Master!$D$2:$D$1000,MATCH(C9,Material_Master!$A$2:$A$1000,0)) -> Coarse sand for concrete (Lawrencepur) | E9: K_ONE | F9: MX_PCC148 | G9: sand | H9: =Coefficients!$D$2*Mix_Design!$K$2 -> 0.47384615 | I9: cft/cft | J9: Mix_Design | K9: =INDEX(Material_Master!$F$2:$F$1000,MATCH(C9,Material_Master!$A$2:$A$1000,0)) -> cft | L9: =INDEX(Material_Master!$Q$2:$Q$1000,MATCH(C9,Material_Master!$A$2:$A$1000,0)) -> 0.1
A10: WI-CN-01 | B10: =INDEX(Work_Items!$D$2:$D$300,MATCH(A10,Work_Items!$A$2:$A$300,0)) -> PCC 1:4:8 in foundation base | C10: CON-008 | D10: =INDEX(Material_Master!$D$2:$D$1000,MATCH(C10,Material_Master!$A$2:$A$1000,0)) -> Crushed stone 1.5in down (or brick ballast) | E10: K_ONE | F10: MX_PCC148 | G10: agg | H10: =Coefficients!$D$2*Mix_Design!$L$2 -> 0.94769231 | I10: cft/cft | J10: Mix_Design | K10: =INDEX(Material_Master!$F$2:$F$1000,MATCH(C10,Material_Master!$A$2:$A$1000,0)) -> cft | L10: =INDEX(Material_Master!$Q$2:$Q$1000,MATCH(C10,Material_Master!$A$2:$A$1000,0)) -> 0.075
A11: WI-CN-02 | B11: =INDEX(Work_Items!$D$2:$D$300,MATCH(A11,Work_Items!$A$2:$A$300,0)) -> PCC 1:4:8 floor base (GF, porch) | C11: CON-001 | D11: =INDEX(Material_Master!$D$2:$D$1000,MATCH(C11,Material_Master!$A$2:$A$1000,0)) -> Ordinary Portland Cement (OPC) - 50 kg bag | E11: K_ONE | F11: MX_PCC148 | G11: cement | H11: =Coefficients!$D$2*Mix_Design!$J$2 -> 0.096608277 | I11: bag/cft | J11: Mix_Design | K11: =INDEX(Material_Master!$F$2:$F$1000,MATCH(C11,Material_Master!$A$2:$A$1000,0)) -> bag | L11: =INDEX(Material_Master!$Q$2:$Q$1000,MATCH(C11,Material_Master!$A$2:$A$1000,0)) -> 0.02
A12: WI-CN-02 | B12: =INDEX(Work_Items!$D$2:$D$300,MATCH(A12,Work_Items!$A$2:$A$300,0)) -> PCC 1:4:8 floor base (GF, porch) | C12: CON-004 | D12: =INDEX(Material_Master!$D$2:$D$1000,MATCH(C12,Material_Master!$A$2:$A$1000,0)) -> Coarse sand for concrete (Lawrencepur) | E12: K_ONE | F12: MX_PCC148 | G12: sand | H12: =Coefficients!$D$2*Mix_Design!$K$2 -> 0.47384615 | I12: cft/cft | J12: Mix_Design | K12: =INDEX(Material_Master!$F$2:$F$1000,MATCH(C12,Material_Master!$A$2:$A$1000,0)) -> cft | L12: =INDEX(Material_Master!$Q$2:$Q$1000,MATCH(C12,Material_Master!$A$2:$A$1000,0)) -> 0.1
A13: WI-CN-02 | B13: =INDEX(Work_Items!$D$2:$D$300,MATCH(A13,Work_Items!$A$2:$A$300,0)) -> PCC 1:4:8 floor base (GF, porch) | C13: CON-008 | D13: =INDEX(Material_Master!$D$2:$D$1000,MATCH(C13,Material_Master!$A$2:$A$1000,0)) -> Crushed stone 1.5in down (or brick ballast) | E13: K_ONE | F13: MX_PCC148 | G13: agg | H13: =Coefficients!$D$2*Mix_Design!$L$2 -> 0.94769231 | I13: cft/cft | J13: Mix_Design | K13: =INDEX(Material_Master!$F$2:$F$1000,MATCH(C13,Material_Master!$A$2:$A$1000,0)) -> cft | L13: =INDEX(Material_Master!$Q$2:$Q$1000,MATCH(C13,Material_Master!$A$2:$A$1000,0)) -> 0.075
A14: WI-CN-03 | B14: =INDEX(Work_Items!$D$2:$D$300,MATCH(A14,Work_Items!$A$2:$A$300,0)) -> RCC 1:2:4 in isolated footings | C14: CON-001 | D14: =INDEX(Material_Master!$D$2:$D$1000,MATCH(C14,Material_Master!$A$2:$A$1000,0)) -> Ordinary Portland Cement (OPC) - 50 kg bag | E14: K_ONE | F14: MX_RCC124 | G14: cement | H14: =Coefficients!$D$2*Mix_Design!$J$4 -> 0.17941537 | I14: bag/cft | J14: Mix_Design | K14: =INDEX(Material_Master!$F$2:$F$1000,MATCH(C14,Material_Master!$A$2:$A$1000,0)) -> bag | L14: =INDEX(Material_Master!$Q$2:$Q$1000,MATCH(C14,Material_Master!$A$2:$A$1000,0)) -> 0.02
A15: WI-CN-03 | B15: =INDEX(Work_Items!$D$2:$D$300,MATCH(A15,Work_Items!$A$2:$A$300,0)) -> RCC 1:2:4 in isolated footings | C15: CON-004 | D15: =INDEX(Material_Master!$D$2:$D$1000,MATCH(C15,Material_Master!$A$2:$A$1000,0)) -> Coarse sand for concrete (Lawrencepur) | E15: K_ONE | F15: MX_RCC124 | G15: sand | H15: =Coefficients!$D$2*Mix_Design!$K$4 -> 0.44 | I15: cft/cft | J15: Mix_Design | K15: =INDEX(Material_Master!$F$2:$F$1000,MATCH(C15,Material_Master!$A$2:$A$1000,0)) -> cft | L15: =INDEX(Material_Master!$Q$2:$Q$1000,MATCH(C15,Material_Master!$A$2:$A$1000,0)) -> 0.1
A16: WI-CN-03 | B16: =INDEX(Work_Items!$D$2:$D$300,MATCH(A16,Work_Items!$A$2:$A$300,0)) -> RCC 1:2:4 in isolated footings | C16: CON-006 | D16: =INDEX(Material_Master!$D$2:$D$1000,MATCH(C16,Material_Master!$A$2:$A$1000,0)) -> Crushed stone 3/4in down (Margalla crush) | E16: K_ONE | F16: MX_RCC124 | G16: agg | H16: =Coefficients!$D$2*Mix_Design!$L$4 -> 0.88 | I16: cft/cft | J16: Mix_Design | K16: =INDEX(Material_Master!$F$2:$F$1000,MATCH(C16,Material_Master!$A$2:$A$1000,0)) -> cft | L16: =INDEX(Material_Master!$Q$2:$Q$1000,MATCH(C16,Material_Master!$A$2:$A$1000,0)) -> 0.075
A17: WI-CN-03 | B17: =INDEX(Work_Items!$D$2:$D$300,MATCH(A17,Work_Items!$A$2:$A$300,0)) -> RCC 1:2:4 in isolated footings | C17: CON-013 | D17: =INDEX(Material_Master!$D$2:$D$1000,MATCH(C17,Material_Master!$A$2:$A$1000,0)) -> Cover blocks / rebar spacers | E17: K_COVERBLK_CFT | H17: =Coefficients!$D$99 -> 1 | I17: Nos/cft | J17: Allowance | K17: =INDEX(Material_Master!$F$2:$F$1000,MATCH(C17,Material_Master!$A$2:$A$1000,0)) -> Nos | L17: =INDEX(Material_Master!$Q$2:$Q$1000,MATCH(C17,Material_Master!$A$2:$A$1000,0)) -> 0.05
A18: WI-CN-04 | B18: =INDEX(Work_Items!$D$2:$D$300,MATCH(A18,Work_Items!$A$2:$A$300,0)) -> RCC in plinth / grade beams | C18: CON-001 | D18: =INDEX(Material_Master!$D$2:$D$1000,MATCH(C18,Material_Master!$A$2:$A$1000,0)) -> Ordinary Portland Cement (OPC) - 50 kg bag | E18: K_ONE | F18: MX_RCC124 | G18: cement | H18: =Coefficients!$D$2*Mix_Design!$J$4 -> 0.17941537 | I18: bag/cft | J18: Mix_Design | K18: =INDEX(Material_Master!$F$2:$F$1000,MATCH(C18,Material_Master!$A$2:$A$1000,0)) -> bag | L18: =INDEX(Material_Master!$Q$2:$Q$1000,MATCH(C18,Material_Master!$A$2:$A$1000,0)) -> 0.02
A19: WI-CN-04 | B19: =INDEX(Work_Items!$D$2:$D$300,MATCH(A19,Work_Items!$A$2:$A$300,0)) -> RCC in plinth / grade beams | C19: CON-004 | D19: =INDEX(Material_Master!$D$2:$D$1000,MATCH(C19,Material_Master!$A$2:$A$1000,0)) -> Coarse sand for concrete (Lawrencepur) | E19: K_ONE | F19: MX_RCC124 | G19: sand | H19: =Coefficients!$D$2*Mix_Design!$K$4 -> 0.44 | I19: cft/cft | J19: Mix_Design | K19: =INDEX(Material_Master!$F$2:$F$1000,MATCH(C19,Material_Master!$A$2:$A$1000,0)) -> cft | L19: =INDEX(Material_Master!$Q$2:$Q$1000,MATCH(C19,Material_Master!$A$2:$A$1000,0)) -> 0.1
A20: WI-CN-04 | B20: =INDEX(Work_Items!$D$2:$D$300,MATCH(A20,Work_Items!$A$2:$A$300,0)) -> RCC in plinth / grade beams | C20: CON-006 | D20: =INDEX(Material_Master!$D$2:$D$1000,MATCH(C20,Material_Master!$A$2:$A$1000,0)) -> Crushed stone 3/4in down (Margalla crush) | E20: K_ONE | F20: MX_RCC124 | G20: agg | H20: =Coefficients!$D$2*Mix_Design!$L$4 -> 0.88 | I20: cft/cft | J20: Mix_Design | K20: =INDEX(Material_Master!$F$2:$F$1000,MATCH(C20,Material_Master!$A$2:$A$1000,0)) -> cft | L20: =INDEX(Material_Master!$Q$2:$Q$1000,MATCH(C20,Material_Master!$A$2:$A$1000,0)) -> 0.075
A21: WI-CN-04 | B21: =INDEX(Work_Items!$D$2:$D$300,MATCH(A21,Work_Items!$A$2:$A$300,0)) -> RCC in plinth / grade beams | C21: CON-013 | D21: =INDEX(Material_Master!$D$2:$D$1000,MATCH(C21,Material_Master!$A$2:$A$1000,0)) -> Cover blocks / rebar spacers | E21: K_COVERBLK_CFT | H21: =Coefficients!$D$99 -> 1 | I21: Nos/cft | J21: Allowance | K21: =INDEX(Material_Master!$F$2:$F$1000,MATCH(C21,Material_Master!$A$2:$A$1000,0)) -> Nos | L21: =INDEX(Material_Master!$Q$2:$Q$1000,MATCH(C21,Material_Master!$A$2:$A$1000,0)) -> 0.05
A22: WI-CN-05 | B22: =INDEX(Work_Items!$D$2:$D$300,MATCH(A22,Work_Items!$A$2:$A$300,0)) -> RCC in columns | C22: CON-001 | D22: =INDEX(Material_Master!$D$2:$D$1000,MATCH(C22,Material_Master!$A$2:$A$1000,0)) -> Ordinary Portland Cement (OPC) - 50 kg bag | E22: K_ONE | F22: MX_RCC124 | G22: cement | H22: =Coefficients!$D$2*Mix_Design!$J$4 -> 0.17941537 | I22: bag/cft | J22: Mix_Design | K22: =INDEX(Material_Master!$F$2:$F$1000,MATCH(C22,Material_Master!$A$2:$A$1000,0)) -> bag | L22: =INDEX(Material_Master!$Q$2:$Q$1000,MATCH(C22,Material_Master!$A$2:$A$1000,0)) -> 0.02
A23: WI-CN-05 | B23: =INDEX(Work_Items!$D$2:$D$300,MATCH(A23,Work_Items!$A$2:$A$300,0)) -> RCC in columns | C23: CON-004 | D23: =INDEX(Material_Master!$D$2:$D$1000,MATCH(C23,Material_Master!$A$2:$A$1000,0)) -> Coarse sand for concrete (Lawrencepur) | E23: K_ONE | F23: MX_RCC124 | G23: sand | H23: =Coefficients!$D$2*Mix_Design!$K$4 -> 0.44 | I23: cft/cft | J23: Mix_Design | K23: =INDEX(Material_Master!$F$2:$F$1000,MATCH(C23,Material_Master!$A$2:$A$1000,0)) -> cft | L23: =INDEX(Material_Master!$Q$2:$Q$1000,MATCH(C23,Material_Master!$A$2:$A$1000,0)) -> 0.1
A24: WI-CN-05 | B24: =INDEX(Work_Items!$D$2:$D$300,MATCH(A24,Work_Items!$A$2:$A$300,0)) -> RCC in columns | C24: CON-006 | D24: =INDEX(Material_Master!$D$2:$D$1000,MATCH(C24,Material_Master!$A$2:$A$1000,0)) -> Crushed stone 3/4in down (Margalla crush) | E24: K_ONE | F24: MX_RCC124 | G24: agg | H24: =Coefficients!$D$2*Mix_Design!$L$4 -> 0.88 | I24: cft/cft | J24: Mix_Design | K24: =INDEX(Material_Master!$F$2:$F$1000,MATCH(C24,Material_Master!$A$2:$A$1000,0)) -> cft | L24: =INDEX(Material_Master!$Q$2:$Q$1000,MATCH(C24,Material_Master!$A$2:$A$1000,0)) -> 0.075
A25: WI-CN-05 | B25: =INDEX(Work_Items!$D$2:$D$300,MATCH(A25,Work_Items!$A$2:$A$300,0)) -> RCC in columns | C25: CON-013 | D25: =INDEX(Material_Master!$D$2:$D$1000,MATCH(C25,Material_Master!$A$2:$A$1000,0)) -> Cover blocks / rebar spacers | E25: K_COVERBLK_CFT | H25: =Coefficients!$D$99 -> 1 | I25: Nos/cft | J25: Allowance | K25: =INDEX(Material_Master!$F$2:$F$1000,MATCH(C25,Material_Master!$A$2:$A$1000,0)) -> Nos | L25: =INDEX(Material_Master!$Q$2:$Q$1000,MATCH(C25,Material_Master!$A$2:$A$1000,0)) -> 0.05
A26: WI-CN-06 | B26: =INDEX(Work_Items!$D$2:$D$300,MATCH(A26,Work_Items!$A$2:$A$300,0)) -> RCC in beams (below slab soffit) | C26: CON-001 | D26: =INDEX(Material_Master!$D$2:$D$1000,MATCH(C26,Material_Master!$A$2:$A$1000,0)) -> Ordinary Portland Cement (OPC) - 50 kg bag | E26: K_ONE | F26: MX_RCC124 | G26: cement | H26: =Coefficients!$D$2*Mix_Design!$J$4 -> 0.17941537 | I26: bag/cft | J26: Mix_Design | K26: =INDEX(Material_Master!$F$2:$F$1000,MATCH(C26,Material_Master!$A$2:$A$1000,0)) -> bag | L26: =INDEX(Material_Master!$Q$2:$Q$1000,MATCH(C26,Material_Master!$A$2:$A$1000,0)) -> 0.02
A27: WI-CN-06 | B27: =INDEX(Work_Items!$D$2:$D$300,MATCH(A27,Work_Items!$A$2:$A$300,0)) -> RCC in beams (below slab soffit) | C27: CON-004 | D27: =INDEX(Material_Master!$D$2:$D$1000,MATCH(C27,Material_Master!$A$2:$A$1000,0)) -> Coarse sand for concrete (Lawrencepur) | E27: K_ONE | F27: MX_RCC124 | G27: sand | H27: =Coefficients!$D$2*Mix_Design!$K$4 -> 0.44 | I27: cft/cft | J27: Mix_Design | K27: =INDEX(Material_Master!$F$2:$F$1000,MATCH(C27,Material_Master!$A$2:$A$1000,0)) -> cft | L27: =INDEX(Material_Master!$Q$2:$Q$1000,MATCH(C27,Material_Master!$A$2:$A$1000,0)) -> 0.1
A28: WI-CN-06 | B28: =INDEX(Work_Items!$D$2:$D$300,MATCH(A28,Work_Items!$A$2:$A$300,0)) -> RCC in beams (below slab soffit) | C28: CON-006 | D28: =INDEX(Material_Master!$D$2:$D$1000,MATCH(C28,Material_Master!$A$2:$A$1000,0)) -> Crushed stone 3/4in down (Margalla crush) | E28: K_ONE | F28: MX_RCC124 | G28: agg | H28: =Coefficients!$D$2*Mix_Design!$L$4 -> 0.88 | I28: cft/cft | J28: Mix_Design | K28: =INDEX(Material_Master!$F$2:$F$1000,MATCH(C28,Material_Master!$A$2:$A$1000,0)) -> cft | L28: =INDEX(Material_Master!$Q$2:$Q$1000,MATCH(C28,Material_Master!$A$2:$A$1000,0)) -> 0.075
A29: WI-CN-06 | B29: =INDEX(Work_Items!$D$2:$D$300,MATCH(A29,Work_Items!$A$2:$A$300,0)) -> RCC in beams (below slab soffit) | C29: CON-013 | D29: =INDEX(Material_Master!$D$2:$D$1000,MATCH(C29,Material_Master!$A$2:$A$1000,0)) -> Cover blocks / rebar spacers | E29: K_COVERBLK_CFT | H29: =Coefficients!$D$99 -> 1 | I29: Nos/cft | J29: Allowance | K29: =INDEX(Material_Master!$F$2:$F$1000,MATCH(C29,Material_Master!$A$2:$A$1000,0)) -> Nos | L29: =INDEX(Material_Master!$Q$2:$Q$1000,MATCH(C29,Material_Master!$A$2:$A$1000,0)) -> 0.05
A30: WI-CN-07 | B30: =INDEX(Work_Items!$D$2:$D$300,MATCH(A30,Work_Items!$A$2:$A$300,0)) -> RCC in floor & roof slabs | C30: CON-001 | D30: =INDEX(Material_Master!$D$2:$D$1000,MATCH(C30,Material_Master!$A$2:$A$1000,0)) -> Ordinary Portland Cement (OPC) - 50 kg bag | E30: K_ONE | F30: MX_RCC124 | G30: cement | H30: =Coefficients!$D$2*Mix_Design!$J$4 -> 0.17941537 | I30: bag/cft | J30: Mix_Design | K30: =INDEX(Material_Master!$F$2:$F$1000,MATCH(C30,Material_Master!$A$2:$A$1000,0)) -> bag | L30: =INDEX(Material_Master!$Q$2:$Q$1000,MATCH(C30,Material_Master!$A$2:$A$1000,0)) -> 0.02
A31: WI-CN-07 | B31: =INDEX(Work_Items!$D$2:$D$300,MATCH(A31,Work_Items!$A$2:$A$300,0)) -> RCC in floor & roof slabs | C31: CON-004 | D31: =INDEX(Material_Master!$D$2:$D$1000,MATCH(C31,Material_Master!$A$2:$A$1000,0)) -> Coarse sand for concrete (Lawrencepur) | E31: K_ONE | F31: MX_RCC124 | G31: sand | H31: =Coefficients!$D$2*Mix_Design!$K$4 -> 0.44 | I31: cft/cft | J31: Mix_Design | K31: =INDEX(Material_Master!$F$2:$F$1000,MATCH(C31,Material_Master!$A$2:$A$1000,0)) -> cft | L31: =INDEX(Material_Master!$Q$2:$Q$1000,MATCH(C31,Material_Master!$A$2:$A$1000,0)) -> 0.1
A32: WI-CN-07 | B32: =INDEX(Work_Items!$D$2:$D$300,MATCH(A32,Work_Items!$A$2:$A$300,0)) -> RCC in floor & roof slabs | C32: CON-006 | D32: =INDEX(Material_Master!$D$2:$D$1000,MATCH(C32,Material_Master!$A$2:$A$1000,0)) -> Crushed stone 3/4in down (Margalla crush) | E32: K_ONE | F32: MX_RCC124 | G32: agg | H32: =Coefficients!$D$2*Mix_Design!$L$4 -> 0.88 | I32: cft/cft | J32: Mix_Design | K32: =INDEX(Material_Master!$F$2:$F$1000,MATCH(C32,Material_Master!$A$2:$A$1000,0)) -> cft | L32: =INDEX(Material_Master!$Q$2:$Q$1000,MATCH(C32,Material_Master!$A$2:$A$1000,0)) -> 0.075
A33: WI-CN-07 | B33: =INDEX(Work_Items!$D$2:$D$300,MATCH(A33,Work_Items!$A$2:$A$300,0)) -> RCC in floor & roof slabs | C33: CON-013 | D33: =INDEX(Material_Master!$D$2:$D$1000,MATCH(C33,Material_Master!$A$2:$A$1000,0)) -> Cover blocks / rebar spacers | E33: K_COVERBLK_CFT | H33: =Coefficients!$D$99 -> 1 | I33: Nos/cft | J33: Allowance | K33: =INDEX(Material_Master!$F$2:$F$1000,MATCH(C33,Material_Master!$A$2:$A$1000,0)) -> Nos | L33: =INDEX(Material_Master!$Q$2:$Q$1000,MATCH(C33,Material_Master!$A$2:$A$1000,0)) -> 0.05
A34: WI-CN-08 | B34: =INDEX(Work_Items!$D$2:$D$300,MATCH(A34,Work_Items!$A$2:$A$300,0)) -> RCC in staircase (waist, steps, landings) | C34: CON-001 | D34: =INDEX(Material_Master!$D$2:$D$1000,MATCH(C34,Material_Master!$A$2:$A$1000,0)) -> Ordinary Portland Cement (OPC) - 50 kg bag | E34: K_ONE | F34: MX_RCC124 | G34: cement | H34: =Coefficients!$D$2*Mix_Design!$J$4 -> 0.17941537 | I34: bag/cft | J34: Mix_Design | K34: =INDEX(Material_Master!$F$2:$F$1000,MATCH(C34,Material_Master!$A$2:$A$1000,0)) -> bag | L34: =INDEX(Material_Master!$Q$2:$Q$1000,MATCH(C34,Material_Master!$A$2:$A$1000,0)) -> 0.02
